<?xml version="1.0" encoding="utf-8" ?>
<!-- This URDF was automatically created by SolidWorks to URDF Exporter! Originally created by Stephen Brawner (brawner@gmail.com) 
     Commit Version: 1.6.0-4-g7f85cfe  Build Version: 1.6.7995.38578
     For more information, please see http://wiki.ros.org/sw_urdf_exporter -->
<robot name="Robot_Snake_URDF">
    <material name="WHITE_MTL">
        <color rgba="1 0 0.0 1.0" />
        <!-- rviz green color -->
    </material>
    <link name="cabeza">
        <inertial>
            <origin xyz="-0.0053245 -0.012546 -0.62044" rpy="0 0 0" />
            <mass value="0.31953" />
            <inertia ixx="0.0003328" ixy="-4.2883E-07" ixz="-2.1318E-07" iyy="0.00032972" iyz="-3.6823E-07" izz="0.00030897" />
        </inertial>
        <visual>
            <origin xyz="0 0 0" rpy="0 0 0" />
            <geometry>
                <mesh filename="package://Robot_Snake_URDF/meshes/cabeza.STL" />
            </geometry>
            <material name="black">
                <color rgba="0 0 0 1" />
            </material>
        </visual>
        <collision>
            <origin xyz="0 0 0" rpy="0 0 0" />
            <geometry>
                <mesh filename="package://Robot_Snake_URDF/meshes/cabeza.STL" />
            </geometry>
        </collision>
    </link>
    <link name="motor1">
        <inertial>
            <origin xyz="-0.012133 0.00057662 -0.00053395" rpy="0 0 0" />
            <mass value="0.055801" />
            <inertia ixx="1.1418E-05" ixy="-4.0337E-09" ixz="-7.8025E-09" iyy="1.5569E-05" iyz="-3.4172E-07" izz="1.5584E-05" />
        </inertial>
        <visual>
            <origin xyz="0 0 0" rpy="0 0 0" />
            <geometry>
                <mesh filename="package://Robot_Snake_URDF/meshes/motor1.STL" />
            </geometry>
            <material name="WHITE_MTL" />
        </visual>
        <collision>
            <origin xyz="0 0 0" rpy="0 0 0" />
            <geometry>
                <mesh filename="package://Robot_Snake_URDF/meshes/motor1.STL" />
            </geometry>
        </collision>
    </link>
    <joint name="cabeza_motor1" type="revolute">
        <origin xyz="-0.007833 -0.011926 -0.57364" rpy="-2.6951 1.563 0.44643" />
        <parent link="cabeza" />
        <child link="motor1" />
        <axis xyz="0 0 1" />
        <limit lower="-1.57" upper="1.57" effort="300" velocity="3" />
    </joint>
    <link name="cuerpo1">
        <inertial>
            <origin xyz="-0.079285 0.0030663 0.0002863" rpy="0 0 0" />
            <mass value="0.5986" />
            <inertia ixx="0.00061574" ixy="1.1352E-05" ixz="4.3049E-07" iyy="0.0013934" iyz="1.1026E-06" izz="0.0013747" />
        </inertial>
        <visual>
            <origin xyz="0 0 0" rpy="0 0 0" />
            <geometry>
                <mesh filename="package://Robot_Snake_URDF/meshes/cuerpo1.STL" />
            </geometry>
            <material name="WHITE_MTL" />
        </visual>
        <collision>
            <origin xyz="0 0 0" rpy="0 0 0" />
            <geometry>
                <mesh filename="package://Robot_Snake_URDF/meshes/cuerpo1.STL" />
            </geometry>
        </collision>
    </link>
    <joint name="motor1_cuerpo1" type="revolute">
        <origin xyz="-0.024188 -4.3298E-05 3.1222E-05" rpy="-1.5708 0 0" />
        <parent link="motor1" />
        <child link="cuerpo1" />
        <axis xyz="0 0 1" />
        <limit lower="-1.57" upper="1.57" effort="300" velocity="3" />
    </joint>
    <link name="motor2">
        <inertial>
            <origin xyz="-0.011868 0.00057823 -0.00053395" rpy="0 0 0" />
            <mass value="0.055801" />
            <inertia ixx="1.1418E-05" ixy="-3.4815E-09" ixz="-7.8479E-09" iyy="1.5569E-05" iyz="-3.4172E-07" izz="1.5584E-05" />
        </inertial>
        <visual>
            <origin xyz="0 0 0" rpy="0 0 0" />
            <geometry>
                <mesh filename="package://Robot_Snake_URDF/meshes/motor2.STL" />
            </geometry>
            <material name="BLACK">
                <color rgba="0.74902 0.74902 0.74902 1" />
            </material>
        </visual>
        <collision>
            <origin xyz="0 0 0" rpy="0 0 0" />
            <geometry>
                <mesh filename="package://Robot_Snake_URDF/meshes/motor2.STL" />
            </geometry>
        </collision>
    </link>
    <joint name="cuerpo1_motor2" type="revolute">
        <origin xyz="-0.15897 0.0021812 5.5449E-05" rpy="1.5708 -0.00016511 -0.014065" />
        <parent link="cuerpo1" />
        <child link="motor2" />
        <axis xyz="0 0 1" />
        <limit lower="-1.57" upper="1.57" effort="300" velocity="3" />
    </joint>
    <link name="cuerpo2">
        <inertial>
            <origin xyz="-0.079332 -0.0014349 -0.00029684" rpy="0 0 0" />
            <mass value="0.5986" />
            <inertia ixx="0.00061561" ixy="4.6451E-06" ixz="-5.0868E-07" iyy="0.0013935" iyz="1.1117E-06" izz="0.0013747" />
        </inertial>
        <visual>
            <origin xyz="0 0 0" rpy="0 0 0" />
            <geometry>
                <mesh filename="package://Robot_Snake_URDF/meshes/cuerpo2.STL" />
            </geometry>
            <material name="WHITE">
                <color rgba="0.25098 0.25098 0.25098 1" />
            </material>
        </visual>
        <collision>
            <origin xyz="0 0 0" rpy="0 0 0" />
            <geometry>
                <mesh filename="package://Robot_Snake_URDF/meshes/cuerpo2.STL" />
            </geometry>
        </collision>
    </link>
    <joint name="motor2_cuerpo2" type="revolute">
        <origin xyz="-0.023922 -4.0084E-05 3.2084E-05" rpy="1.5708 0 0" />
        <parent link="motor2" />
        <child link="cuerpo2" />
        <axis xyz="0 0 1" />
        <limit lower="-1.57" upper="1.57" effort="300" velocity="3" />
    </joint>
    <link name="motor3">
        <inertial>
            <origin xyz="-0.011991 0.00057822 -0.00053349" rpy="0 0 0" />
            <mass value="0.055801" />
            <inertia ixx="1.1418E-05" ixy="-3.4815E-09" ixz="-7.8479E-09" iyy="1.5569E-05" iyz="-3.4172E-07" izz="1.5584E-05" />
        </inertial>
        <visual>
            <origin xyz="0 0 0" rpy="0 0 0" />
            <geometry>
                <mesh filename="package://Robot_Snake_URDF/meshes/motor3.STL" />
            </geometry>
            <material name="WHITE_MTL">
                <color rgba="0.0 1.0 0.0 1.0" />
            </material>
        </visual>
        <collision>
            <origin xyz="0 0 0" rpy="0 0 0" />
            <geometry>
                <mesh filename="package://Robot_Snake_URDF/meshes/motor3.STL" />
            </geometry>
        </collision>
    </link>
    <joint name="cuerpo2_motor3" type="revolute">
        <origin xyz="-0.15886 0.0010874 -7.6586E-05" rpy="-1.5708 0.0013629 -0.0065004" />
        <parent link="cuerpo2" />
        <child link="motor3" />
        <axis xyz="0 0 1" />
        <limit lower="-1.57" upper="1.57" effort="300" velocity="3" />
    </joint>
    <link name="cuerpo3">
        <inertial>
            <origin xyz="-0.079348 -0.0019091 -0.00029677" rpy="0 0 0" />
            <mass value="0.5986" />
            <inertia ixx="0.00061558" ixy="-5.8806E-09" ixz="-5.1526E-07" iyy="0.0013935" iyz="1.109E-06" izz="0.0013747" />
        </inertial>
        <visual>
            <origin xyz="0 0 0" rpy="0 0 0" />
            <geometry>
                <mesh filename="package://Robot_Snake_URDF/meshes/cuerpo3.STL" />
            </geometry>
            <material name="">
                <color rgba="0.25098 0.25098 0.25098 1" />
            </material>
        </visual>
        <collision>
            <origin xyz="0 0 0" rpy="0 0 0" />
            <geometry>
                <mesh filename="package://Robot_Snake_URDF/meshes/cuerpo3.STL" />
            </geometry>
        </collision>
    </link>
    <joint name="motor3_cuerpo3" type="revolute">
        <origin xyz="-0.024019 -4.0032E-05 3.2153E-05" rpy="1.5708 0 0" />
        <parent link="motor3" />
        <child link="cuerpo3" />
        <axis xyz="0 0 1" />
        <limit lower="-1.57" upper="1.57" effort="300" velocity="3" />
    </joint>
    <link name="motor4">
        <inertial>
            <origin xyz="-0.012 0.00057822 -0.00053348" rpy="0 0 0" />
            <mass value="0.055801" />
            <inertia ixx="1.1418E-05" ixy="-3.4815E-09" ixz="-7.8479E-09" iyy="1.5569E-05" iyz="-3.4172E-07" izz="1.5584E-05" />
        </inertial>
        <visual>
            <origin xyz="0 0 0" rpy="0 0 0" />
            <geometry>
                <mesh filename="package://Robot_Snake_URDF/meshes/motor4.STL" />
            </geometry>
            <material name="">
                <color rgba="0.74902 0.74902 0.74902 1" />
            </material>
        </visual>
        <collision>
            <origin xyz="0 0 0" rpy="0 0 0" />
            <geometry>
                <mesh filename="package://Robot_Snake_URDF/meshes/motor4.STL" />
            </geometry>
        </collision>
    </link>
    <joint name="cuerpo3_motor4" type="revolute">
        <origin xyz="-0.15888 0.00013761 -7.6531E-05" rpy="-1.5708 0.0018431 -0.00052174" />
        <parent link="cuerpo3" />
        <child link="motor4" />
        <axis xyz="0 0 1" />
        <limit lower="-1.57" upper="1.57" effort="300" velocity="3" />
    </joint>
    <link name="cola">
        <inertial>
            <origin xyz="-0.046936 0.00084233 -0.00057852" rpy="0 0 0" />
            <mass value="0.31953" />
            <inertia ixx="0.00030897" ixy="2.7858E-07" ixz="3.9503E-07" iyy="0.00032972" iyz="4.1943E-07" izz="0.00033279" />
        </inertial>
        <visual>
            <origin xyz="0 0 0" rpy="0 0 0" />
            <geometry>
                <mesh filename="package://Robot_Snake_URDF/meshes/cola.STL" />
            </geometry>
            <material name="">
                <color rgba="0.25098 0.25098 0.25098 1" />
            </material>
        </visual>
        <collision>
            <origin xyz="0 0 0" rpy="0 0 0" />
            <geometry>
                <mesh filename="package://Robot_Snake_URDF/meshes/cola.STL" />
            </geometry>
        </collision>
    </link>
    <joint name="motor4_cola" type="revolute">
        <origin xyz="-0.023994 -4E-05 3.2138E-05" rpy="1.5708 0 0" />
        <parent link="motor4" />
        <child link="cola" />
        <axis xyz="0 0 1" />
        <limit lower="-1.57" upper="1.57" effort="300" velocity="3" />
    </joint>
    <transmission name="link_1_trans">
        <type>transmission_interface/SimpleTransmission</type>
        <joint name="joint_1">
            <hardwareInterface>hardware_interface/PositionJointInterface</hardwareInterface>
        </joint>
        <actuator name="link_1_motor">
            <hardwareInterface>hardware_interface/PositionJointInterface</hardwareInterface>
            <mechanicalReduction>1</mechanicalReduction>
        </actuator>
    </transmission>
    <transmission name="link_2_trans">
        <type>transmission_interface/SimpleTransmission</type>
        <joint name="joint_2">
            <hardwareInterface>hardware_interface/PositionJointInterface</hardwareInterface>
        </joint>
        <actuator name="link_2_motor">
            <hardwareInterface>hardware_interface/PositionJointInterface</hardwareInterface>
            <mechanicalReduction>1</mechanicalReduction>
        </actuator>
    </transmission>
    <transmission name="link_3_trans">
        <type>transmission_interface/SimpleTransmission</type>
        <joint name="joint_3">
            <hardwareInterface>hardware_interface/PositionJointInterface</hardwareInterface>
        </joint>
        <actuator name="link_3_motor">
            <hardwareInterface>hardware_interface/PositionJointInterface</hardwareInterface>
            <mechanicalReduction>1</mechanicalReduction>
        </actuator>
    </transmission>
    <transmission name="link_4_trans">
        <type>transmission_interface/SimpleTransmission</type>
        <joint name="joint_4">
            <hardwareInterface>hardware_interface/PositionJointInterface</hardwareInterface>
        </joint>
        <actuator name="link_4_motor">
            <hardwareInterface>hardware_interface/PositionJointInterface</hardwareInterface>
            <mechanicalReduction>1</mechanicalReduction>
        </actuator>
    </transmission>
    <transmission name="link_5_trans">
        <type>transmission_interface/SimpleTransmission</type>
        <joint name="joint_5">
            <hardwareInterface>hardware_interface/PositionJointInterface</hardwareInterface>
        </joint>
        <actuator name="link_5_motor">
            <hardwareInterface>hardware_interface/PositionJointInterface</hardwareInterface>
            <mechanicalReduction>1</mechanicalReduction>
        </actuator>
    </transmission>
    <transmission name="link_6_trans">
        <type>transmission_interface/SimpleTransmission</type>
        <joint name="joint_6">
            <hardwareInterface>hardware_interface/PositionJointInterface</hardwareInterface>
        </joint>
        <actuator name="link_6_motor">
            <hardwareInterface>hardware_interface/PositionJointInterface</hardwareInterface>
            <mechanicalReduction>1</mechanicalReduction>
        </actuator>
    </transmission>
    <transmission name="link_7_trans">
        <type>transmission_interface/SimpleTransmission</type>
        <joint name="joint_7">
            <hardwareInterface>hardware_interface/PositionJointInterface</hardwareInterface>
        </joint>
        <actuator name="link_7_motor">
            <hardwareInterface>hardware_interface/PositionJointInterface</hardwareInterface>
            <mechanicalReduction>1</mechanicalReduction>
        </actuator>
    </transmission>
    <transmission name="link_8_trans">
        <type>transmission_interface/SimpleTransmission</type>
        <joint name="joint_8">
            <hardwareInterface>hardware_interface/PositionJointInterface</hardwareInterface>
        </joint>
        <actuator name="link_8_motor">
            <hardwareInterface>hardware_interface/PositionJointInterface</hardwareInterface>
            <mechanicalReduction>1</mechanicalReduction>
        </actuator>
    </transmission>
    <!--ESTALINEAFUECOMENTADA<gazebo>
	 <plugin name="control"filename="libgazebo_ros_control.so">
	<robotNamespace>/</robotNamespace>
	</plugin>
  </gazebo> -->
    <gazebo reference="cabeza">
        <material>Gazebo/Green</material>
        <mu1>0.2</mu1>
        <mu2>0.2</mu2>
        <selfCollide>true</selfCollide>
        <plugin name="gazebo_ros_control">
            <robotNamespace>/</robotNamespace>
        </plugin>
    </gazebo>
    <gazebo reference="motor1">
        <material>Gazebo/Gray</material>
        <mu1>0.2</mu1>
        <mu2>0.2</mu2>
        <selfCollide>true</selfCollide>
    </gazebo>
    <gazebo reference="cuerpo1">
        <material>Gazebo/Green</material>
        <mu1>0.2</mu1>
        <mu2>0.2</mu2>
        <selfCollide>true</selfCollide>
    </gazebo>
    <gazebo reference="motor2">
        <selfCollide>true</selfCollide>
        <material>Gazebo/Gray</material>
        <mu1>0.2</mu1>
        <mu2>0.2</mu2>
        <selfCollide>true</selfCollide>
    </gazebo>
    <gazebo reference="cuerpo2">
        <material>Gazebo/Green</material>
        <mu1>0.2</mu1>
        <mu2>0.2</mu2>
        <selfCollide>true</selfCollide>
    </gazebo>
    <gazebo reference="motor3">
        <material>Gazebo/Gray</material>
        <mu1>0.2</mu1>
        <mu2>0.2</mu2>
        <selfCollide>true</selfCollide>
    </gazebo>
    <gazebo reference="cuerpo3">
        <material>Gazebo/Green</material>
        <mu1>0.2</mu1>
        <mu2>0.2</mu2>
        <selfCollide>true</selfCollide>
    </gazebo>
    <gazebo reference="motor4">
        <material>Gazebo/Gray</material>
        <mu1>0.2</mu1>
        <mu2>0.2</mu2>
        <selfCollide>true</selfCollide>
    </gazebo>
    <gazebo reference="cola">
        <material>Gazebo/Green</material>
        <mu1>0.2</mu1>
        <mu2>0.2</mu2>
        <selfCollide>true</selfCollide>
    </gazebo>
    <transmission name="trans_cabeza_motor1">
        <type>transmission_interface/SimpleTransmission</type>
        <joint name="cabeza_motor1">
            <hardwareInterface>hardware_interface/PositionJointInterface</hardwareInterface>
        </joint>
        <actuator name="cabeza_motor1_motor">
            <hardwareInterface>hardware_interface/PositionJointInterface</hardwareInterface>
            <mechanicalReduction>1</mechanicalReduction>
        </actuator>
    </transmission>
    <transmission name="trans_motor1_cuerpo1">
        <type>transmission_interface/SimpleTransmission</type>
        <joint name="motor1_cuerpo1">
            <hardwareInterface>hardware_interface/PositionJointInterface</hardwareInterface>
        </joint>
        <actuator name="motor1_cuerpo1_motor">
            <hardwareInterface>hardware_interface/PositionJointInterface</hardwareInterface>
            <mechanicalReduction>1</mechanicalReduction>
        </actuator>
    </transmission>
    <transmission name="trans_cuerpo1_motor2">
        <type>transmission_interface/SimpleTransmission</type>
        <joint name="cuerpo1_motor2">
            <hardwareInterface>hardware_interface/PositionJointInterface</hardwareInterface>
        </joint>
        <actuator name="cuerpo1_motor2_motor">
            <hardwareInterface>hardware_interface/PositionJointInterface</hardwareInterface>
            <mechanicalReduction>1</mechanicalReduction>
        </actuator>
    </transmission>
    <transmission name="trans_motor2_cuerpo2">
        <type>transmission_interface/SimpleTransmission</type>
        <joint name="motor2_cuerpo2">
            <hardwareInterface>hardware_interface/PositionJointInterface</hardwareInterface>
        </joint>
        <actuator name="motor2_cuerpo2_motor">
            <hardwareInterface>hardware_interface/PositionJointInterface</hardwareInterface>
            <mechanicalReduction>1</mechanicalReduction>
        </actuator>
    </transmission>
    <transmission name="trans_cuerpo2_motor3">
        <type>transmission_interface/SimpleTransmission</type>
        <joint name="cuerpo2_motor3">
            <hardwareInterface>hardware_interface/PositionJointInterface</hardwareInterface>
        </joint>
        <actuator name="cuerpo2_motor3_motor">
            <hardwareInterface>hardware_interface/PositionJointInterface</hardwareInterface>
            <mechanicalReduction>1</mechanicalReduction>
        </actuator>
    </transmission>
    <transmission name="trans_motor3_cuerpo3">
        <type>transmission_interface/SimpleTransmission</type>
        <joint name="motor3_cuerpo3">
            <hardwareInterface>hardware_interface/PositionJointInterface</hardwareInterface>
        </joint>
        <actuator name="motor3_cuerpo3_motor">
            <hardwareInterface>hardware_interface/PositionJointInterface</hardwareInterface>
            <mechanicalReduction>1</mechanicalReduction>
        </actuator>
    </transmission>
    <transmission name="trans_cuerpo3_motor4">
        <type>transmission_interface/SimpleTransmission</type>
        <joint name="cuerpo3_motor4">
            <hardwareInterface>hardware_interface/PositionJointInterface</hardwareInterface>
        </joint>
        <actuator name="cuerpo3_motor4_motor">
            <hardwareInterface>hardware_interface/PositionJointInterface</hardwareInterface>
            <mechanicalReduction>1</mechanicalReduction>
        </actuator>
    </transmission>
    <transmission name="trans_motor4_cola">
        <type>transmission_interface/SimpleTransmission</type>
        <joint name="motor4_cola">
            <hardwareInterface>hardware_interface/PositionJointInterface</hardwareInterface>
        </joint>
        <actuator name="motor4_cola_motor">
            <hardwareInterface>hardware_interface/PositionJointInterface</hardwareInterface>
            <mechanicalReduction>1</mechanicalReduction>
        </actuator>
    </transmission>
</robot>

